Workbook

Sheet Read Me
A1: Chase-Lift Soaring Register
A2: Compiled 2026-09-22 for Martin (GBSC). Rates, policies and fleets are as published by each operator on that date; anything marked 'unverified' or 'call' needs a phone call before a trip.
A4: Sheets
A5: Operators: one row per site. Rank = ease of short-notice rental for a visiting licensed pilot (1 = easiest) within its region; 0 = not ranked.
A6: Rental Procedures: what it takes to rent, costs, tall-pilot notes, sources.
A7: Fleet Register: every glider found, with N-number where the FAA registry or fleet page gave one; performance columns pull from Glider Types.
A8: Glider Types: glide ratio, speeds, span and cockpit notes per type.
A9: Travel: flight tiers from Boston on a Friday evening.
A10: Contact Log: fill this in as you build relationships (one row per call/email/visit).
A12: Rental categories
A13: RENT: Rents to visitors
A14: GUEST: Guest / short-term membership
... A29: Tall-pilot rule: sit in the actual glider before planning a trip around it. Tall-pilot notes are general type reputation unless the operator stated a limit.

Sheet Operators
A1: ID | B1: Operator | C1: Type | D1: Region | E1: Airport | F1: Town | G1: Access | H1: Travel from Newton | I1: Soaring | J1: Season / days | K1: Rental status | L1: Rank | M1: Gliders listed | N1: Phone | O1: Email | P1: Contacts | Q1: Website | R1: Lat | S1: Lon | T1: Last verified
A2: SUGAR | B2: Sugarbush Soaring | C2: Commercial-style club | D2: New England | E2: Warren-Sugarbush (0B7) | F2: Warren, VT | G2: Van, about 4 h | H2: 191 mi; 3:15 typical, 3:45-4:00 Fri | I2: Thermal, ridge, wave | J2: 7 days (closed Tue), roughly May-Oct; airport closed Nov-Apr | K2: Rents to visitors | L2: 1 | M2: =COUNTIF('Fleet Register'!$A:$A,A2) -> 5 | N2: 802-496-2290 | O2: (via website) | P2: Not published | Q2: https://sugarbushsoaring.com/ | R2: 44.1174 | S2: -72.827 | T2: 2026-09-22
A3: GBSC | B3: Greater Boston Soaring Club (home club) | C3: Club | D3: New England | E3: Sterling (3B3) | F3: Sterling, MA | G3: Van, 4 h or less | H3: 45 mi; 0:50 typical, 1:15-1:30 Fri evening | I3: Thermal | J3: Weekends + holidays, Apr-Nov; some weekdays | K3: Membership required | L3: 2 | M3: =COUNTIF('Fleet Register'!$A:$A,A3) -> 8 | N3: (field phone not published) | O3: membership@soargbsc.com | P3: Tony Verhulst (groups.io); Dwight Schirmer (treasurer); Ken Flaton (evening ground school) | Q3: https://www.soargbsc.net/ | R3: 42.4259 | S3: -71.7929 | T3: 2026-09-22
A4: MOHAWK | B4: Mohawk Soaring Club | C4: Club | D4: New England | E4: Harriman-and-West (AQW) | F4: North Adams, MA | G4: Van, 4 h or less | H4: ~135 mi; 2:40 typical, 3:10 Fri | I4: Ridge (Mt Greylock, Taconics), thermal | J4: Saturdays + one midweek day (usually Wed), Apr-Nov | K4: Guest / short-term membership | L4: 3 | M4: =COUNTIF('Fleet Register'!$A:$A,A4) -> 6 | N4: (not published) | O4: doug.herrick at rcn.com (rides) | P4: Doug Herrick (rides); Jon Goodman (president, 2022) | Q4: http://www.soarmohawk.com/ | R4: 42.6963 | S4: -73.1706 | T4: 2026-09-22
A5: POSTMILLS | B5: Post Mills Soaring Club | C5: Club | D5: New England | E5: Post Mills (2B9) | F5: Post Mills, VT | G5: Van, 4 h or less | H5: 155 mi; 2:40 typical, 3:10 Fri | I5: Thermal | J5: Weekends assumed (unverified), spring-fall | K5: Membership required | L5: 4 | M5: =COUNTIF('Fleet Register'!$A:$A,A5) -> 4 | N5: 802-333-9401 | O5: andrew.e.lumley@gmail.com | P5: Andy Lumley (membership + airport manager, 802-266-1355) | Q5: https://flypmsc.org/ | R5: 43.8837 | S5: -72.2521 | T5: 2026-09-22
A6: NESA | B6: New England Soaring Association | C6: Club | D6: New England | E6: Hartness State (VSF) | F6: Springfield, VT | G6: Van, 4 h or less | H6: 123 mi; 2:15 typical, 2:45 Fri | I6: Thermal | J6: Mostly weekends, Apr-Nov | K6: Membership required | L6: 5 | M6: =COUNTIF('Fleet Register'!$A:$A,A6) -> 4 | N6: (not published) | O6: (web form) | P6: Jim Malecha (pres.), Larry Perry (VP), Andy Kozak (sec.), Jerry Smith (treas.) | Q6: https://www.flynesa.com/ | R6: 43.3437 | S6: -72.5173 | T6: 2026-09-22
A7: FRANCONIA | B7: Franconia Soaring Association | C7: Club | D7: New England | E7: Franconia (1B5) | F7: Franconia, NH | G7: Van, 4 h or less | H7: 151 mi; 2:30 typical, 3:00-3:30 Fri | I7: Thermal, ridge (Cannon/Kinsman), wave | J7: Weekends + holidays, Fri by arrangement, ~May-Oct | K7: Unknown, call | L7: 6 | M7: =COUNTIF('Fleet Register'!$A:$A,A7) -> 7 | N7: 603-823-5034 | O7: franconiasoaring@gmail.com | P7: James R. David (airport manager, 603-921-1588) | Q7: http://www.franconiasoaring.org/ | R7: 44.196 | S7: -71.7507 | T7: 2026-09-22
A8: CSA | B8: Connecticut Soaring Association | C8: Club | D8: New England | E8: Windham (IJD) | F8: Windham, CT | G8: Van, 4 h or less | H8: 84 mi; 1:30 typical, 2:00 Fri | I8: Thermal | J8: ~Apr-Nov; midweek program since 2024 | K8: Membership required | L8: 7 | M8: =COUNTIF('Fleet Register'!$A:$A,A8) -> 4 | N8: 860-202-1866 | O8: contact@ctsoaring.org | P8: Not published | Q8: https://www.ctsoaring.org/ | R8: 41.744 | S8: -72.1802 | T8: 2026-09-22
A9: GORHAM | B9: Mt Washington Wave Camp (GBSC/Franconia/Post Mills) | C9: Event | D9: New England | E9: Gorham (2G8) | F9: Gorham, NH | G9: Van, about 4 h | H9: 183 mi; 3:15 typical, 3:45-4:15 Fri | I9: Wave (Mt Washington) | J9: ~10 days mid-October (Columbus Day) | K9: Membership required | M9: =COUNTIF('Fleet Register'!$A:$A,A9) -> 0 | N9: (via GBSC) | O9: (via GBSC) | P9: Run jointly by host clubs | Q9: https://www.soargbsc.com/wave/MtWashBrief.pdf | R9: 44.3931 | S9: -71.1967 | T9: 2026-09-22
A10: SANFORD | B10: Sanford Soaring | C10: Club? | D10: New England | E10: Sanford Seacoast (SFM) | F10: Sanford, ME | G10: Van, 4 h or less | H10: 92 mi; 1:40 typical, 2:15 Fri | I10: Thermal, sea breeze | J10: Unknown | K10: Closed / inactive | M10: =COUNTIF('Fleet Register'!$A:$A,A10) -> 0 | Q10: https://www.facebook.com/sanfordsoaring/ | R10: 43.3938 | S10: -70.708 | T10: 2026-09-22
A11: SPIRIT | B11: Spirit Soaring (motorglider rides) | C11: Commercial | D11: New England | E11: Knox County (RKD) | F11: Owls Head, ME | G11: Van, about 4 h | H11: 195 mi; 3:15 typical, 3:45-4:00 Fri | I11: Coastal | J11: Unknown | K11: Closed / inactive | M11: =COUNTIF('Fleet Register'!$A:$A,A11) -> 0 | P11: Dave Miramant | Q11: https://www.spiritsoaring.org/ | R11: 44.0601 | S11: -69.0997 | T11: 2026-09-22
A12: WURTS | B12: Wurtsboro Airport / Wurtsboro Flight Mgmt | C12: Commercial | D12: NY/NJ/PA | E12: Wurtsboro-Sullivan County (N82) | F12: Wurtsboro, NY | G12: Van, about 4 h | H12: 216 mi; 3:30 typical, 4:00-4:15 Fri | I12: Ridge (Shawangunk), thermal | J12: 7 days, year-round (weather) | K12: Rents to visitors | L12: 1 | M12: =COUNTIF('Fleet Register'!$A:$A,A12) -> 4 | N12: (845) 888-2791 | O12: info@wurtsboroairport.com | P12: Not published | Q12: https://www.wurtsboroairport.com/ | R12: 41.5972 | S12: -74.4583 | T12: 2026-09-22
A13: VANSANT | B13: Van Sant Airport / Bird of Paradise | C13: Commercial | D13: NY/NJ/PA | E13: Van Sant (9N1) | F13: Erwinna, PA | G13: Fly Friday night | H13: PHL + 1:15 (drive 5:00+) | I13: Thermal, some ridge | J13: Tue-Sun 9-4, year-round | K13: Rents to visitors | L13: 2 | M13: =COUNTIF('Fleet Register'!$A:$A,A13) -> 2 | N13: (610) 847-1119 | P13: Office (610) 847-8494 | Q13: https://vansantairport.com/ | R13: 40.4842 | S13: -75.0997 | T13: 2026-09-22
A14: HHSC | B14: Harris Hill Soaring Corp | C14: Club | D14: NY/NJ/PA | E14: Harris Hill Gliderport (4NY8) | F14: Elmira, NY | G14: Fly Friday night | H14: 5:30 drive; or SYR + 1:45 / BUF + 2:30 | I14: Ridge, thermal | J14: ~Apr-Oct; weekends (daily Jun-mid Aug) | K14: Guest / short-term membership | L14: 3 | M14: =COUNTIF('Fleet Register'!$A:$A,A14) -> 7 | N14: (607) 734-0641 | O14: newmember@ / training@harrishillsoaring.org | Q14: https://harrishillsoaring.org/ | R14: 42.1209 | S14: -76.9011 | T14: 2026-09-22
A15: PSA | B15: Pittsburgh Soaring Association | C15: Club | D15: NY/NJ/PA | E15: Greene County (WAY) | F15: Waynesburg, PA | G15: Fly Friday night | H15: PIT + ~1:00 | I15: Thermal | J15: Weekends | K15: Guest / short-term membership | L15: 4 | M15: =COUNTIF('Fleet Register'!$A:$A,A15) -> 3 | Q15: http://pghsoar.org/ | R15: 39.9 | S15: -80.133 | T15: 2026-09-22
A16: ASA | B16: Adirondack Soaring Association | C16: Club | D16: NY/NJ/PA | E16: Saratoga County (5B2) | F16: Ballston Spa, NY | G16: Van, 4 h or less | H16: 193 mi; 3:15 typical, 3:45 Fri | I16: Thermal, some ridge | J16: Every weekend + some weekdays, Apr-Nov | K16: Guest / short-term membership | L16: 5 | M16: =COUNTIF('Fleet Register'!$A:$A,A16) -> 4 | N16: (518) 693-6849 | O16: (web) | P16: Eric Davenport (pres.); Tim Hanke (dir. of ops) | Q16: https://www.adirondacksoaring.com/ | R16: 43.0512 | S16: -73.8612 | T16: 2026-09-22
A17: ACA | B17: Aero Club Albatross | C17: Club | D17: NY/NJ/PA | E17: Blairstown (1N7) + Wurtsboro (N82) | F17: Blairstown, NJ | G17: Out of range | H17: 266 mi to Blairstown; 4:45-5:00 Fri (Wurtsboro ~4:00) | I17: Ridge (Kittatinny, Shawangunk), thermal | J17: Wurtsboro 7 days; Blairstown weekends | K17: Membership required | L17: 6 | M17: =COUNTIF('Fleet Register'!$A:$A,A17) -> 8 | N17: (973) 294-5146 | O17: AeroClubAlbatross@gmail.com | P17: Not published | Q17: https://www.aeroclubalbatross.org/ | R17: 40.9712 | S17: -74.9975 | T17: 2026-09-22
A18: FLSC | B18: Finger Lakes Soaring Club | C18: Club | D18: NY/NJ/PA | E18: Dansville (DSV) | F18: Dansville, NY | G18: Fly Friday night | H18: BUF/ROC + ~1:00 | I18: Thermal | J18: Weekends 9-5, Apr-Nov | K18: Guest / short-term membership | L18: 7 | M18: =COUNTIF('Fleet Register'!$A:$A,A18) -> 5 | N18: (585) 335-5849 | O18: contact@flsc.org | P18: Rick Lafford (airport mgr, 585-444-3612) | Q18: https://flsc.org/ | R18: 42.571 | S18: -77.713 | T18: 2026-09-22
A19: JRS | B19: Jersey Ridge Soaring | C19: Commercial | D19: NY/NJ/PA | E19: Blairstown (1N7) | F19: Blairstown, NJ | G19: Out of range | H19: 266 mi; 4:15 typical, 4:45-5:00 Fri; or PHL + 1:45 | I19: Ridge (Kittatinny), thermal | J19: Weekends, year-round; tows 7 days | K19: Unknown, call | L19: 8 | M19: =COUNTIF('Fleet Register'!$A:$A,A19) -> 4 | N19: (908) 362-1239 | O19: info@jerseyridgesoaring.com | P19: Kevin & Brenda Martin (owners); Michael Friedman (chief instructor) | Q19: https://www.jerseyridgesoaring.com/ | R19: 40.973 | S19: -74.995 | T19: 2026-09-22
A20: BSA | B20: Brandywine Soaring Association | C20: Club | D20: NY/NJ/PA | E20: New Garden (N57) | F20: Toughkenamon, PA | G20: Fly Friday night | H20: PHL + ~1:00 | I20: Thermal | J20: Wed + weekends, May-Oct | K20: Guest / short-term membership | L20: 9 | M20: =COUNTIF('Fleet Register'!$A:$A,A20) -> 4 | O20: membership@brandywinesoaring.org | Q20: https://www.brandywinesoaring.org/ | R20: 39.831 | S20: -75.77 | T20: 2026-09-22
A21: VSC | B21: Valley Soaring Club | C21: Club | D21: NY/NJ/PA | E21: Randall (06N) | F21: Middletown, NY | G21: Van, about 4 h | H21: ~3:30 typical, ~4:00 Fri | I21: Thermal | J21: Weekends + Mon holidays, Apr-Dec | K21: Unknown, call | L21: 10 | M21: =COUNTIF('Fleet Register'!$A:$A,A21) -> 4 | N21: (845) 564-2054 | Q21: (login-only site) | R21: 41.4319 | S21: -74.3916 | T21: 2026-09-22
A22: PGC | B22: Philadelphia Glider Council | C22: Club | D22: NY/NJ/PA | E22: Philadelphia Gliderport (3PA2) | F22: Hilltown, PA | G22: Fly Friday night | H22: PHL + ~1:00 | I22: Thermal | J22: Weekends | K22: Membership required | L22: 11 | M22: =COUNTIF('Fleet Register'!$A:$A,A22) -> 4 | N22: 215-334-5980 | Q22: https://pgcsoaring.org/ | R22: 40.3312 | S22: -75.2481 | T22: 2026-09-22
A23: TIGERS | B23: Soaring Tigers | C23: Club | D23: NY/NJ/PA | E23: Van Sant (9N1) | F23: Erwinna, PA | G23: Fly Friday night | H23: PHL + 1:15 | I23: Thermal | J23: Wed-Sun | K23: Membership required | L23: 13 | M23: =COUNTIF('Fleet Register'!$A:$A,A23) -> 3 | N23: (610) 847-1119 | Q23: https://soaringtigers.org/ | R23: 40.486 | S23: -75.0975 | T23: 2026-09-22
A24: LISA | B24: Long Island Soaring Association | C24: Club | D24: NY/NJ/PA | E24: Brookhaven Calabro (HWV) | F24: Shirley, NY | G24: Out of range | H24: 4+ h | I24: Thermal (flat coastal) | J24: Weekends, some Wed | K24: Membership required | L24: 14 | M24: =COUNTIF('Fleet Register'!$A:$A,A24) -> 3 | N24: 631-578-8596 | Q24: https://longislandsoaring.com/ | R24: 40.822 | S24: -72.869 | T24: 2026-09-22
A25: SKYLINE | B25: Skyline Soaring Club | C25: Club | D25: Mid-Atlantic | E25: Front Royal (FRR); at Petersburg WV (W99) from 16 Sep 2026 | F25: Front Royal, VA | G25: Fly Friday night | H25: IAD + ~1:00 (Petersburg ~2:45) | I25: Thermal, ridge; wave at Petersburg | J25: Weekends + some weekdays | K25: Guest / short-term membership | L25: 2 | M25: =COUNTIF('Fleet Register'!$A:$A,A25) -> 3 | O25: welcome@skylinesoaring.org | Q25: https://www.skylinesoaring.org/ | R25: 38.9175 | S25: -78.2535 | T25: 2026-09-22
A26: BRSS | B26: Blue Ridge Soaring Society | C26: Club | D26: Mid-Atlantic | E26: New Castle (VA85) | F26: New Castle, VA | G26: Fly Friday night | H26: IAD/CLT/RDU + 3:30-4:00 | I26: Ridge, wave (to 23,000 ft), thermal | J26: Weekends | K26: Guest / short-term membership | L26: 5 | M26: =COUNTIF('Fleet Register'!$A:$A,A26) -> 2 | N26: 540-864-5800 (airport owner) | O26: (web form) | P26: Lanier Frantz (airport owner) | Q26: https://www.brss.net/ | R26: 37.4835 | S26: -80.0998 | T26: 2026-09-22
A27: SVS | B27: Shenandoah Valley Soaring | C27: Club | D27: Mid-Atlantic | E27: Rockfish Gliderport (VG22) | F27: Nellysford, VA | G27: Fly Friday night | H27: IAD/DCA + ~2:45-3:00 | I27: Thermal, ridge | J27: Weekends, year-round | K27: Guest / short-term membership | L27: 6 | M27: =COUNTIF('Fleet Register'!$A:$A,A27) -> 2 | O27: (web form) | Q27: https://www.svsoar.org/ | R27: 37.8788 | S27: -78.8935 | T27: 2026-09-22
A28: MASA | B28: Mid-Atlantic Soaring Association | C28: Club | D28: Mid-Atlantic | E28: Fairfield (W73) | F28: Fairfield, PA | G28: Fly Friday night | H28: BWI/IAD + ~1:30 | I28: Thermal, ridge, wave | J28: Mar-Nov | K28: Membership required | L28: 12 | M28: =COUNTIF('Fleet Register'!$A:$A,A28) -> 5 | N28: 717-642-9907 (airport) | O28: joinus@midatlanticsoaring.org | P28: Mark Philip (airport mgr) | Q28: https://midatlanticsoaring.org/ | R28: 39.757 | S28: -77.3514 | T28: 2026-09-22
A29: ESC | B29: Eastern Soaring Center | C29: Commercial | D29: Mid-Atlantic | E29: Grant County (W99) | F29: Petersburg, WV | G29: Fly Friday night | H29: IAD + ~2:45 | I29: Thermal, ridge, wave (FL230 window) | J29: Closed for 2026 | K29: Closed / inactive | M29: =COUNTIF('Fleet Register'!$A:$A,A29) -> 1 | N29: 304-851-4106 | O29: gliding@EasternSoaringCenter.com | P29: Brian Collins (owner, DPE) | Q29: https://www.easternsoaringcenter.com/ | R29: 38.9914 | S29: -79.1456 | T29: 2026-09-22
A30: TSS | B30: Tidewater Soaring Society | C30: Club | D30: Mid-Atlantic | E30: Garner (3VA8) | F30: Windsor, VA | G30: Fly Friday night | H30: RDU + 2:45 | I30: Thermal | J30: Weekends, year-round | K30: Membership required | M30: =COUNTIF('Fleet Register'!$A:$A,A30) -> 0 | N30: 757-377-6174 (landing permission) | P30: W.E. Laine Jr. | Q30: https://tss.fyi/ | R30: 36.8563 | S30: -76.6822 | T30: 2026-09-22
A31: CHIL | B31: Chilhowee Gliderport | C31: Commercial | D31: Southeast | E31: Chilhowee (92A) | F31: Benton, TN | G31: Fly Friday night | H31: ATL + 2:15; BNA + 3:00 | I31: Thermal (spring-fall), ridge (fall-spring), occasional wave | J31: Fri-Sun 11:00-sunset, year-round | K31: Rents to visitors | L31: 1 | M31: =COUNTIF('Fleet Register'!$A:$A,A31) -> 5 | N31: 423-338-2000 (cell 423-506-9015) | O31: info@chilhowee.com | P31: Sarah Arnold (bookings) | Q31: https://www.chilhowee.com/ | R31: 35.2265 | S31: -84.5849 | T31: 2026-09-22
A32: BHS | B32: Bermuda High Soaring | C32: Commercial + club | D32: Southeast | E32: Bermuda High Gliderport (SC79) | F32: Jefferson, SC | G32: Fly Friday night | H32: CLT + 1:15 | I32: Thermal | J32: Weekends 10-5, year-round | K32: Unknown, call | L32: 4 | M32: =COUNTIF('Fleet Register'!$A:$A,A32) -> 3 | N32: (803) 475-7627 | P32: Jayne Ewing Reid; Frank Reid | Q32: https://bermudahighsoaring.com/ | R32: 34.6113 | S32: -80.4498 | T32: 2026-09-22
A33: CAROLINA | B33: Carolina Soaring Association | C33: Club | D33: Southeast | E33: Spartanburg Downtown (SPA) | F33: Spartanburg, SC | G33: Fly Friday night | H33: CLT + 1:15 | I33: Thermal | J33: Weekends | K33: Membership required | M33: =COUNTIF('Fleet Register'!$A:$A,A33) -> 2 | N33: 864-256-1741 | Q33: https://carolinasoaring.org/ | R33: 34.9157 | S33: -81.9565 | T33: 2026-09-22
A34: NCSA | B34: North Carolina Soaring Association | C34: Club | D34: Southeast | E34: Crooked Creek (7NC5) | F34: Bunn, NC | G34: Fly Friday night | H34: RDU + 0:45 | I34: Thermal | J34: Every weekend day | K34: Membership required | M34: =COUNTIF('Fleet Register'!$A:$A,A34) -> 0 | N34: 919-215-1356 (field owner) | O34: info@soaringnc.org | P34: Frank Swett | Q34: https://soaringnc.org/ | R34: 35.9312 | S34: -78.2448 | T34: 2026-09-22
A35: MGSA | B35: Mid-Georgia Soaring Association | C35: Club | D35: Southeast | E35: Monroe (D73) | F35: Monroe, GA | G35: Fly Friday night | H35: ATL + 1:00 | I35: Thermal | J35: Most weekends | K35: Membership required | M35: =COUNTIF('Fleet Register'!$A:$A,A35) -> 3 | O35: membershipinfo@soar-mgsa.org | Q35: https://www.soar-mgsa.org/ | R35: 33.7823 | S35: -83.6926 | T35: 2026-09-22
A36: EAGLEVILLE | B36: Eagleville Soaring Club | C36: Club | D36: Southeast | E36: Puckett Gliderport (50M) | F36: Eagleville, TN | G36: Fly Friday night | H36: BNA + 0:45 | I36: Thermal | J36: Most weekends, year-round | K36: Membership required | M36: =COUNTIF('Fleet Register'!$A:$A,A36) -> 3 | N36: 800-306-6690 | O36: info@eaglevillesoaring.org | Q36: https://eaglevillesoaring.org/ | R36: 35.6894 | S36: -86.615 | T36: 2026-09-22
A37: SANDHILL | B37: Sandhill Soaring Club | C37: Club | D37: Midwest | E37: Richmond Field (69G) | F37: Gregory, MI | G37: Fly Friday night | H37: DTW + 1:00 | I37: Thermal | J37: Weekends Apr-Nov + weekdays | K37: Guest / short-term membership | L37: 3 | M37: =COUNTIF('Fleet Register'!$A:$A,A37) -> 5 | N37: 734-498-2075 (field mgr) | P37: Michael Campbell (field mgr) | Q37: https://www.sandhillsoaring.org/ | R37: 42.442 | S37: -84.0643 | T37: 2026-09-22
A38: SKYSOAR | B38: Sky Soaring | C38: Club | D38: Midwest | E38: Sky Soaring (55LL) | F38: Hampshire, IL | G38: Fly Friday night | H38: ORD + 0:50 | I38: Thermal | J38: Mid-Apr-Oct | K38: Membership required | M38: =COUNTIF('Fleet Register'!$A:$A,A38) -> 4 | N38: (847) 683-7627 | Q38: https://skysoaring.com/ | R38: 42.1542 | S38: -88.5115 | T38: 2026-09-22
A39: CGC | B39: Chicago Glider Club | C39: Club | D39: Midwest | E39: Chicago Glider Club (IL59) | F39: Minooka, IL | G39: Fly Friday night | H39: MDW + 0:50 | I39: Thermal | J39: Apr-Oct | K39: Membership required | M39: =COUNTIF('Fleet Register'!$A:$A,A39) -> 3 | N39: 630-854-9456 | P39: Ron Ridenour (manager) | Q39: http://www.chicagogliderclub.org/ | R39: 41.432 | S39: -88.2473 | T39: 2026-09-22
A40: CCSC | B40: Caesar Creek Soaring Club | C40: Club | D40: Midwest | E40: Caesar Creek Gliderport (2OH9) | F40: Waynesville, OH | G40: Fly Friday night | H40: CMH + 1:15 | I40: Thermal | J40: Weekends + Wed, year-round | K40: Membership required | M40: =COUNTIF('Fleet Register'!$A:$A,A40) -> 4 | N40: 513-932-7627 | O40: ccsc@soarccsc.com | Q40: https://www.soarccsc.com/ | R40: 39.4767 | S40: -84.0938 | T40: 2026-09-22
...

Sheet Rental Procedures
A1: ID | B1: Operator | C1: Rental status | D1: Procedure for a visiting licensed pilot | E1: Costs | F1: Tall-pilot notes | G1: Sources
A2: SUGAR | B2: Sugarbush Soaring | C2: Rents to visitors | D2: Publishes non-member glider rental rates (only such operator in New England). Checkout, currency and insurance rules not published (unverified): expect dual checkout in PW-6 or 2-33 plus site briefing. Ask whether a documented checkout stays valid for later visits. | E2: Non-member rental: PW-6U $169/h, 2-33 $85/h, 1-26E $79/h (20 min min). Non-member tow $28 + $3.30/100 ft (2,000 ft = $94). Instruction $59-86/h. Membership $875 share + $750/yr (YP 22-35: $175/yr). | F2: 2-33 roomy; PW-6 front seat fairly roomy (sit-test). | G2: https://sugarbushsoaring.com/doc/rate-sheet-2026.pdf ; https://sugarbushsoaring.com/about-us/fleet-aircraft
A3: GBSC | B3: Greater Boston Soaring Club (home club) | C3: Membership required | D3: Members only; no rental to non-members. Once rated: checkout in each two-seater (front and back seat) and a cockpit checkout before each single-seater. Club flights limited to 1 h. Visiting private owners only: Region 1 owners pay member tow rates; others $15/day temporary membership + $60 flat tow, max 5 visits/yr, SSA required. | E3: Regular $600 initiation (over 2 yr) + $750/yr; 90-day trial membership exists. Tow $14 hookup + $1.60/100 ft (min 1,200 ft). Instruction free. | F3: You do not fit the ASK-21. Sit-test the 1-34, L-23 and ASW-19 now; the 2-33 is roomy. | G3: https://www.soargbsc.net/index.php/gbsc_fleet ; https://www.soargbsc.net/fee_schedule
A4: MOHAWK | B4: Mohawk Soaring Club | C4: Guest / short-term membership | D4: No rental without membership. Advertises a short-term reduced-rate 'Limited membership'; $150 ride includes a 30-day limited membership with follow-up flights $50. Terms for rated pilots unverified: email ahead. | E4: Quarterly dues (amount unpublished); instruction free; club says average flight under $60. | F4: L-13 Blanik and 2-33 are roomy types. | G4: http://www.soarmohawk.com/membership/ ; FAA registry
A5: POSTMILLS | B5: Post Mills Soaring Club | C5: Membership required | D5: No visitor rental; full-season membership needed for solo. Trial membership ($100/flight, one-time) and temporary student membership exist. SSA required. Cottages on field. | E5: $450 initiation + $450/yr. Tow $18 + $10/1,000 ft. Glider use appears included in dues. Instruction free. | F5: L-23 Super Blanik and 2-33 are good tall-pilot types. | G5: https://flypmsc.org/ ; 2025 rates Google Doc
A6: NESA | B6: New England Soaring Association | C6: Membership required | D6: No visitor rental. Join (cheap), then checkout; short-notice flying once a member. | E6: $300 initiation + $300/yr + SSA. Gliders $10/flight. Tow $30 pattern to $70 at 5,000 ft. Instruction free. | F6: 2-33 and 1-34 likely fit. | G6: https://www.flynesa.com/about-us/our-fleet/ ; 2025 fee schedule PDF
A7: FRANCONIA | B7: Franconia Soaring Association | C7: Unknown, call | D7: Visitor rules unverified (membership pages blocked). Assume membership needed; call. Six CFIGs, first come first served. | E7: Rides $120 (3,000 ft) / $200 (5,000 ft). Membership rates not retrieved. | F7: Grob 103 Twin Astir is your best two-seat bet here; L-23 and 2-33 roomy. | G7: http://www.franconiasoaring.org/ ; FAA registry
A8: CSA | B8: Connecticut Soaring Association | C8: Membership required | D8: Must join; terms unpublished. Short of CFIGs and tow pilots. | E8: Not published. | F8: FAQ: cannot accommodate anyone over 6 ft 1 in / 220 lb (written for passengers). Poor fit. | G8: https://www.ctsoaring.org/our-fleet ; https://www.ctsoaring.org/faq
A9: GORHAM | B9: Mt Washington Wave Camp (GBSC/Franconia/Post Mills) | C9: Membership required | D9: An event, not an operator. Fly your own club's gliders; oxygen and wave-window checkouts apply. | E9: Per club. | F9: Per club fleet. | G9: https://www.soargbsc.com/wave/MtWashBrief.pdf
A10: SANFORD | B10: Sanford Soaring | C10: Closed / inactive | D10: Website not updated since 2019; no club-registered gliders found. Status unknown. | G10: Facebook page
A11: SPIRIT | B11: Spirit Soaring (motorglider rides) | C11: Closed / inactive | D11: Rides only in a Grob 109 motorglider; website no longer resolves. Not a rental option. | G11: Reviews to 2020
A12: WURTS | B12: Wurtsboro Airport / Wurtsboro Flight Mgmt | C12: Rents to visitors | D12: Public commercial rental. Rental-requirements page could not be read: expect instructor checkout, possibly minimum hours. Do one checkout day before relying on short-notice trips; ask currency rule. | E12: Rental: Grob 103 $75/h, 2-33 $67/h, 1-26E $55/h. Tow to 2,500 ft $74.07, +$20/1,000 ft. Instruction $65-67/h. | F12: 2-33 good; Grob 103 depends on proportions; 1-26 poor. | G12: https://www.wurtsboroairport.com/rates
A13: VANSANT | B13: Van Sant Airport / Bird of Paradise | C13: Rents to visitors | D13: 'Licensed glider pilots may also rent.' Checkout/currency rules not published; expect a checkout. | E13: Rental 2-33 $80/h, 2-32 $80/h + tows. Tow $50 (1,000) / $60 (2,000) / $65 (3,000) / $100 (5,000). Instruction $120 + tow. | F13: 2-33 and 2-32 both roomy. | G13: https://vansantairport.com/rides-and-rental-prices/
A14: HHSC | B14: Harris Hill Soaring Corp | C14: Guest / short-term membership | D14: 'Board approved guest' category: $20/day, rental $50/h. Email ahead for guest approval; checkout in 2-33, 1-34 or Duo Discus. Non-members: tows only. | E14: Guest $20/day; rental $50/h; tow $20 + $30/1,000 ft. Senior member $300 + $30/mo; rental $9-25/h. | F14: 2-33 and Duo Discus good; ASK-21 no. | G14: https://harrishillsoaring.org/wp-content/uploads/2026/02/2026-rates.pdf
A15: PSA | B15: Pittsburgh Soaring Association | C15: Guest / short-term membership | D15: 'Temporary memberships are available for visiting pilots' (price unpublished). | E15: Rental $10/h; tow $25 + $5/1,000 ft; full $60/mo + ~$500 buy-in. | F15: Grob 102 and L-23 good. | G15: http://pghsoar.org/fly-with-us/
A16: ASA | B16: Adirondack Soaring Association | C16: Guest / short-term membership | D16: Long-Distance membership (live 120+ mi away): full fleet access; book on Click N Glide. Board approval + SSA. Checkout Grob 103 then Grob 102. | E16: Long-Distance $650 initiation + $15/month; gliders + instruction included; tows only ($40 to 2,000 ft, 2022). | F16: All-Grob fleet: Grob 102 roomiest; Grob 103 depends on proportions. | G16: https://www.adirondacksoaring.com/membership
A17: ACA | B17: Aero Club Albatross | C17: Membership required | D17: Full membership (licensed pilots): apply, attend a monthly meeting (3rd Thu, Denville NJ), wing-runner course, checkout. No hourly glider charge afterwards. | E17: $1,000 initiation (or $250/yr x4) + $138 dues + $530/yr flight fee + SSA. Tow 2,000 ft $38 with season pass. | F17: 2-33 and LS-4 good; Twin Astir depends on proportions. | G17: https://www.aeroclubalbatross.org/memberships/
A18: FLSC | B18: Finger Lakes Soaring Club | C18: Guest / short-term membership | D18: Long Distance membership; 'Guest' status for pilots of other SSA clubs (orientation). Seasonal check ride; 1-26 needs 15 flights in type. | E18: Long Distance $550 ($200 refundable) + $15/mo. Tow $18/1,000 ft; winch $8.50. | F18: Grob 102 and 2-33 good. | G18: https://flsc.org/MembershipJoinUs.php
A19: JRS | B19: Jersey Ridge Soaring | C19: Unknown, call | D19: Website lists tows for private owners and ACA members; no solo-rental policy published. Call about checkout + rental of 2-33 / 1-26. | E19: Lessons $130-160. | F19: 2-33 and 2-32 good. | G19: http://www.jerseyridgesoaring.com/Lessons.html
A20: BSA | B20: Brandywine Soaring Association | C20: Guest / short-term membership | D20: Non-resident membership (100+ mi); waiting list, faster for rated pilots. | E20: $500 + $35/mo; tow 3,000 ft $44. | F20: L-23 roomy; ASK-21 no. | G20: brandywinesoaring.org membership page
A21: VSC | B21: Valley Soaring Club | C21: Unknown, call | D21: Membership terms unpublished; call. | F21: 2-33 good. | G21: FlightSchoolList; FAA registry
A22: PGC | B22: Philadelphia Glider Council | C22: Membership required | D22: Full membership only. | E22: $1,090/yr + $700 entry + $100 bond; tows ~$35. | F22: Grob 102 roomy; Grob 103s depend on proportions. | G22: https://pgcsoaring.org/glider-club-membership.php
A23: TIGERS | B23: Soaring Tigers | C23: Membership required | D23: Annual membership only; tows only after that. | E23: $700/yr after solo; tows $35-90. | F23: Pilot weight limits 191-385 lb by glider. | G23: https://soaringtigers.org/memberinfo.html
A24: LISA | B24: Long Island Soaring Association | C24: Membership required | D24: 3 prepaid guest flights + 2 meetings before joining. Poor fit for chasing lift. | E24: Guest flight $120 then $60; $800 + $66/mo; tow $21 to 1,000 ft. | F24: 2-33 good. | G24: https://longislandsoaring.com/fees
A25: SKYLINE | B25: Skyline Soaring Club | C25: Guest / short-term membership | D25: 'Visiting Member' $10/day for members of SSA-affiliated clubs, max 5 days/yr. Introductory $75 for 45 days. Email with SSA number + logbook; expect checkout. | E25: ASK-21 $39/h, Discus CS $36/h (capped 3 h), PW-5 $24/h. Tow $30 to 1,000 ft + $1/100 ft. | F25: ASK-21 won't fit; Discus CS medium (sit-test). | G25: https://www.skylinesoaring.org/cms/ssc-documents/dues-fees/
A26: BRSS | B26: Blue Ridge Soaring Society | C26: Guest / short-term membership | D26: Monthly guest memberships, club approval. Tows and instruction members only. | E26: Unpublished. | F26: ASK-21, LS-4, LS-6: poor fit. | G26: https://www.brss.net/visitor-info/
A27: SVS | B27: Shenandoah Valley Soaring | C27: Guest / short-term membership | D27: 3-month introductory membership (from demo flight). Height limit under 6'5", 230 lb. | E27: Unpublished. | F27: Under 6'5" limit. | G27: https://www.svsoar.org/faqs.html
A28: MASA | B28: Mid-Atlantic Soaring Association | C28: Membership required | D28: Full membership, provisional first year, 5 duty days. No visitor membership. Pilot weight ~154-240 lb. | E28: $1,000 initiation + $695/yr + SSA. | F28: Mostly ASK-21; 2-33A only likely fit. | G28: midatlanticsoaring.org join page
A29: ESC | B29: Eastern Soaring Center | C29: Closed / inactive | D29: Rents to rated pilots with an ESC airfield/winch checkride in last 12 months. Closed for 2026 season; watch for 2027. | E29: ASK-13 $55/h; winch $30-60. | F29: ASK-13 roomy. | G29: https://www.easternsoaringcenter.com/
A30: TSS | B30: Tidewater Soaring Society | C30: Membership required | D30: Membership only. | E30: $300 + $200 deposit + $45/mo + SSA. | F30: 2-33A good. | G30: http://www.tidewatersoaring.org/membership.html
A31: CHIL | B31: Chilhowee Gliderport | C31: Rents to visitors | D31: Commercial hourly rental, no membership. Expect dual checkout (2-33A) first visit. Block account $1,000 buys $1,100 credit (forfeited after 1 yr idle). After that, call Thursday. | E31: 2-33A $48/h, PW-6U $72/h, 1-26E $40/h, PW-5 $48/h (15 min min). Tow $20 + $2/100 ft ($40 min). Instruction $60/h. | F31: 2-33A best; PW-6U fairly roomy; 2-32 very roomy (dual only). | G31: https://www.chilhowee.com/rates.html
A32: BHS | B32: Bermuda High Soaring | C32: Unknown, call | D32: 'Not scheduling instruction at this time'; members first. Call about rental. | E32: Ride $120 (2-33); weight limit 230-240 lb. | F32: 2-33 and Duo Discus good. | G32: https://bermudahighsoaring.com/contact-us.html
A33: CAROLINA | B33: Carolina Soaring Association | C33: Membership required | D33: Contact before a trip; no visitor option published. | E33: $250 + $82/mo; gliders $0/h; aerotow $7 + $2.17/100 ft; winch $12. | F33: Grob 103 roomy. | G33: https://carolinasoaring.org/rates/
A34: NCSA | B34: North Carolina Soaring Association | C34: Membership required | D34: 'Drop by anytime we are flying'; fleet and rates unpublished. | G34: https://soaringnc.org/
A35: MGSA | B35: Mid-Georgia Soaring Association | C35: Membership required | D35: Membership only. | E35: $500 + $450/yr + $500 capital note + SSA; tow 2,000 ft ~$50. | F35: ASK-21s; Grob 102 maybe. | G35: https://www.soar-mgsa.org/membershipinfo
A36: EAGLEVILLE | B36: Eagleville Soaring Club | C36: Membership required | D36: No visitor option published. | F36: ASK-21s, LS-4: poor fit ('height limited if significantly above 6 ft'). | G36: https://eaglevillesoaring.org/
A37: SANDHILL | B37: Sandhill Soaring Club | C37: Guest / short-term membership | D37: 'Short-term Guest Membership may be arranged for licensed soaring pilots.' Price unpublished. | E37: Tow min $26 + $1/100 ft above 1,000 ft. | F37: DG-505, Grob 103, 2-33: best tall-pilot club fleet. | G37: https://www.sandhillsoaring.org/join
A38: SKYSOAR | B38: Sky Soaring | C38: Membership required | D38: Accepting 1 new member this season; no visitor option. | E38: $250 + $725/yr + $1,000 buy-in; tows $25-55. | F38: 2-33A, KR-03 Puchatek good. | G38: https://skysoaring.com/membership/
A39: CGC | B39: Chicago Glider Club | C39: Membership required | D39: Sponsor required; long-term commitment. | E39: $1,200 + $552/yr; ships $36-40/h. | F39: Duo Discus front seat roomy. | G39: chicagogliderclub.org fees
A40: CCSC | B40: Caesar Creek Soaring Club | C40: Membership required | D40: Full membership required to act as PIC. | E40: $1,000 + $38/mo + 12 SSD shares ($100 ea). | F40: 2-33s, Grob 102. | G40: https://www.soarccsc.com/membership/
...

Sheet Glider Types
A1: Type key | B1: Type | C1: Class | D1: Seats | E1: Span (m) | F1: Max L/D | G1: Best-glide speed (kt) | H1: Min sink (fpm) | I1: Vne (kt) | J1: Cockpit / tall pilot | K1: Figures approximate?
A2: 2-33 | B2: Schweizer SGS 2-33A | C2: Trainer (metal) | D2: 2 | E2: 15.5 | F2: 23 | G2: 39 | H2: 185 | I2: 85 | J2: Roomy | K2: No
A3: 2-32 | B3: Schweizer SGS 2-32 | C3: Two-seat (metal) | D3: 3 | E3: 17.4 | F3: 34 | G3: 51 | H3: 144 | I3: 137 | J3: Roomy | K3: No
A4: 2-22 | B4: Schweizer SGU 2-22 | C4: Trainer (vintage) | D4: 2 | E4: 13.4 | F4: 17 | G4: 42 | H4: 197 | I4: 63 | J4: Tight | K4: Yes, verify
A5: 1-26 | B5: Schweizer SGS 1-26 | C5: One-design (metal) | D5: 1 | E5: 12.2 | F5: 23 | G5: 46 | H5: 161 | I5: 99 | J5: Tight headroom | K5: No
A6: 1-34 | B6: Schweizer SGS 1-34 | C6: Standard (metal) | D6: 1 | E6: 15 | F6: 34 | G6: 46 | H6: 132 | I6: 114 | J6: OK | K6: No
A7: 1-35 | B7: Schweizer SGS 1-35 | C7: 15 m (metal) | D7: 1 | E7: 15 | F7: 38 | G7: 52 | H7: 120 | I7: 130 | J7: Reclined, check | K7: Yes, verify
A8: 1-36 | B8: Schweizer SGS 1-36 Sprite | C8: Sport (metal) | D8: 1 | E8: 14.1 | F8: 31 | G8: 46 | H8: 132 | I8: 105 | J8: OK | K8: Yes, verify
A9: 1-23 | B9: Schweizer SGS 1-23 | C9: Standard (vintage metal) | D9: 1 | E9: 15.2 | F9: 29 | G9: 43 | H9: 138 | I9: 121 | J9: Unknown | K9: Yes, verify
A10: L-23 | B10: LET L-23 Super Blanik | C10: Trainer (metal) | D10: 2 | E10: 16.2 | F10: 28 | G10: 49 | H10: 148 | I10: 135 | J10: Roomy | K10: No
A11: L-13 | B11: LET L-13 Blanik | C11: Trainer (metal) | D11: 2 | E11: 16.2 | F11: 28 | G11: 46 | H11: 161 | I11: 137 | J11: Roomy | K11: No
A12: L-33 | B12: LET L-33 Solo | C12: Club (metal) | D12: 1 | E12: 14.1 | F12: 34 | G12: 46 | H12: 130 | I12: 135 | J12: OK | K12: Yes, verify
A13: ASK-21 | B13: Schleicher ASK-21 | C13: Two-seat trainer (GRP) | D13: 2 | E13: 17 | F13: 34 | G13: 49 | H13: 128 | I13: 151 | J13: Tight for very tall (did not fit Martin) | K13: No
... A35: CIRRUS | B35: Schempp-Hirth Open Cirrus | C35: Open (GRP, vintage) | D35: 1 | E35: 17.7 | F35: 44 | G35: 51 | H35: 108 | I35: 119 | J35: Unknown | K35: Yes, verify
A37: Nominal type figures (manufacturer data / type references). L/D = maximum glide ratio; Vne = never-exceed speed; min sink = lowest still-air sink rate. Always use the actual aircraft's flight manual.

Sheet Fleet Register
A1: Operator ID | B1: Operator | C1: Glider | D1: Type key | E1: Registration (N-number) | F1: Seats | G1: Rate | H1: Who can fly it | I1: Tall-pilot note | J1: Max L/D | K1: Best-glide kt | L1: Min sink fpm | M1: Vne kt | N1: Sat in it? (Y/N) | O1: My checkout date | P1: Notes
A2: GBSC | B2: Greater Boston Soaring Club (home club) | C2: Schleicher ASK-21 | D2: ASK-21 | E2: N421GB | F2: 2 | G2: $25/h members | H2: Members | I2: Did not fit you | J2: =IFERROR(INDEX('Glider Types'!$F:$F,MATCH(D2,'Glider Types'!$A:$A,0)),"") -> 34 | K2: =IFERROR(INDEX('Glider Types'!$G:$G,MATCH(D2,'Glider Types'!$A:$A,0)),"") -> 49 | L2: =IFERROR(INDEX('Glider Types'!$H:$H,MATCH(D2,'Glider Types'!$A:$A,0)),"") -> 128 | M2: =IFERROR(INDEX('Glider Types'!$I:$I,MATCH(D2,'Glider Types'!$A:$A,0)),"") -> 151
A3: GBSC | B3: Greater Boston Soaring Club (home club) | C3: Schleicher ASK-21 | D3: ASK-21 | E3: N721RC | F3: 2 | G3: $25/h members | H3: Members | I3: Did not fit you | J3: =IFERROR(INDEX('Glider Types'!$F:$F,MATCH(D3,'Glider Types'!$A:$A,0)),"") -> 34 | K3: =IFERROR(INDEX('Glider Types'!$G:$G,MATCH(D3,'Glider Types'!$A:$A,0)),"") -> 49 | L3: =IFERROR(INDEX('Glider Types'!$H:$H,MATCH(D3,'Glider Types'!$A:$A,0)),"") -> 128 | M3: =IFERROR(INDEX('Glider Types'!$I:$I,MATCH(D3,'Glider Types'!$A:$A,0)),"") -> 151
A4: GBSC | B4: Greater Boston Soaring Club (home club) | C4: Schweizer 2-33A | D4: 2-33 | E4: N1225S | F4: 2 | G4: $14/h members | H4: Members | I4: Roomy | J4: =IFERROR(INDEX('Glider Types'!$F:$F,MATCH(D4,'Glider Types'!$A:$A,0)),"") -> 23 | K4: =IFERROR(INDEX('Glider Types'!$G:$G,MATCH(D4,'Glider Types'!$A:$A,0)),"") -> 39 | L4: =IFERROR(INDEX('Glider Types'!$H:$H,MATCH(D4,'Glider Types'!$A:$A,0)),"") -> 185 | M4: =IFERROR(INDEX('Glider Types'!$I:$I,MATCH(D4,'Glider Types'!$A:$A,0)),"") -> 85
A5: GBSC | B5: Greater Boston Soaring Club (home club) | C5: LET L-23 Super Blanik | D5: L-23 | E5: not found | F5: 2 | G5: $14/h members | H5: Members | I5: Roomy; sit-test | J5: =IFERROR(INDEX('Glider Types'!$F:$F,MATCH(D5,'Glider Types'!$A:$A,0)),"") -> 28 | K5: =IFERROR(INDEX('Glider Types'!$G:$G,MATCH(D5,'Glider Types'!$A:$A,0)),"") -> 49 | L5: =IFERROR(INDEX('Glider Types'!$H:$H,MATCH(D5,'Glider Types'!$A:$A,0)),"") -> 148 | M5: =IFERROR(INDEX('Glider Types'!$I:$I,MATCH(D5,'Glider Types'!$A:$A,0)),"") -> 135
A6: GBSC | B6: Greater Boston Soaring Club (home club) | C6: Schleicher ASW-19B | D6: ASW-19 | E6: not found | F6: 1 | G6: $20/h, 2 h limit | H6: Members | I6: Tight above ~6'2" | J6: =IFERROR(INDEX('Glider Types'!$F:$F,MATCH(D6,'Glider Types'!$A:$A,0)),"") -> 38.5 | K6: =IFERROR(INDEX('Glider Types'!$G:$G,MATCH(D6,'Glider Types'!$A:$A,0)),"") -> 54 | L6: =IFERROR(INDEX('Glider Types'!$H:$H,MATCH(D6,'Glider Types'!$A:$A,0)),"") -> 118 | M6: =IFERROR(INDEX('Glider Types'!$I:$I,MATCH(D6,'Glider Types'!$A:$A,0)),"") -> 138
A7: GBSC | B7: Greater Boston Soaring Club (home club) | C7: LET L-33 Solo | D7: L-33 | E7: not found | F7: 1 | G7: $10/h, 2 h limit | H7: Members | I7: Probably OK | J7: =IFERROR(INDEX('Glider Types'!$F:$F,MATCH(D7,'Glider Types'!$A:$A,0)),"") -> 34 | K7: =IFERROR(INDEX('Glider Types'!$G:$G,MATCH(D7,'Glider Types'!$A:$A,0)),"") -> 46 | L7: =IFERROR(INDEX('Glider Types'!$H:$H,MATCH(D7,'Glider Types'!$A:$A,0)),"") -> 130 | M7: =IFERROR(INDEX('Glider Types'!$I:$I,MATCH(D7,'Glider Types'!$A:$A,0)),"") -> 135
A8: GBSC | B8: Greater Boston Soaring Club (home club) | C8: Schweizer 1-34 | D8: 1-34 | E8: N1156S | F8: 1 | G8: $10/h | H8: Members | I8: Generally good | J8: =IFERROR(INDEX('Glider Types'!$F:$F,MATCH(D8,'Glider Types'!$A:$A,0)),"") -> 34 | K8: =IFERROR(INDEX('Glider Types'!$G:$G,MATCH(D8,'Glider Types'!$A:$A,0)),"") -> 46 | L8: =IFERROR(INDEX('Glider Types'!$H:$H,MATCH(D8,'Glider Types'!$A:$A,0)),"") -> 132 | M8: =IFERROR(INDEX('Glider Types'!$I:$I,MATCH(D8,'Glider Types'!$A:$A,0)),"") -> 114
A9: GBSC | B9: Greater Boston Soaring Club (home club) | C9: Schweizer 1-26E | D9: 1-26 | E9: N33917 | F9: 1 | G9: $10/h | H9: Members | I9: Small | J9: =IFERROR(INDEX('Glider Types'!$F:$F,MATCH(D9,'Glider Types'!$A:$A,0)),"") -> 23 | K9: =IFERROR(INDEX('Glider Types'!$G:$G,MATCH(D9,'Glider Types'!$A:$A,0)),"") -> 46 | L9: =IFERROR(INDEX('Glider Types'!$H:$H,MATCH(D9,'Glider Types'!$A:$A,0)),"") -> 161 | M9: =IFERROR(INDEX('Glider Types'!$I:$I,MATCH(D9,'Glider Types'!$A:$A,0)),"") -> 99
A10: SUGAR | B10: Sugarbush Soaring | C10: PZL PW-6U | D10: PW-6 | E10: N16VT | F10: 2 | G10: $169/h non-member; $50 member | H10: Yes | I10: Front seat fairly roomy | J10: =IFERROR(INDEX('Glider Types'!$F:$F,MATCH(D10,'Glider Types'!$A:$A,0)),"") -> 34 | K10: =IFERROR(INDEX('Glider Types'!$G:$G,MATCH(D10,'Glider Types'!$A:$A,0)),"") -> 51 | L10: =IFERROR(INDEX('Glider Types'!$H:$H,MATCH(D10,'Glider Types'!$A:$A,0)),"") -> 146 | M10: =IFERROR(INDEX('Glider Types'!$I:$I,MATCH(D10,'Glider Types'!$A:$A,0)),"") -> 140
A11: SUGAR | B11: Sugarbush Soaring | C11: PZL PW-6U | D11: PW-6 | E11: N777VT | F11: 2 | G11: $169/h non-member; $50 member | H11: Yes | I11: Front seat fairly roomy | J11: =IFERROR(INDEX('Glider Types'!$F:$F,MATCH(D11,'Glider Types'!$A:$A,0)),"") -> 34 | K11: =IFERROR(INDEX('Glider Types'!$G:$G,MATCH(D11,'Glider Types'!$A:$A,0)),"") -> 51 | L11: =IFERROR(INDEX('Glider Types'!$H:$H,MATCH(D11,'Glider Types'!$A:$A,0)),"") -> 146 | M11: =IFERROR(INDEX('Glider Types'!$I:$I,MATCH(D11,'Glider Types'!$A:$A,0)),"") -> 140
A12: SUGAR | B12: Sugarbush Soaring | C12: Schweizer 2-33 | D12: 2-33 | E12: N2743H | F12: 2 | G12: $85/h non-member; $40 member | H12: Yes | I12: Roomy | J12: =IFERROR(INDEX('Glider Types'!$F:$F,MATCH(D12,'Glider Types'!$A:$A,0)),"") -> 23 | K12: =IFERROR(INDEX('Glider Types'!$G:$G,MATCH(D12,'Glider Types'!$A:$A,0)),"") -> 39 | L12: =IFERROR(INDEX('Glider Types'!$H:$H,MATCH(D12,'Glider Types'!$A:$A,0)),"") -> 185 | M12: =IFERROR(INDEX('Glider Types'!$I:$I,MATCH(D12,'Glider Types'!$A:$A,0)),"") -> 85
A13: SUGAR | B13: Sugarbush Soaring | C13: Schweizer 2-33 | D13: 2-33 | E13: not found | F13: 2 | G13: $85/h non-member; $40 member | H13: Yes | I13: Roomy | J13: =IFERROR(INDEX('Glider Types'!$F:$F,MATCH(D13,'Glider Types'!$A:$A,0)),"") -> 23 | K13: =IFERROR(INDEX('Glider Types'!$G:$G,MATCH(D13,'Glider Types'!$A:$A,0)),"") -> 39 | L13: =IFERROR(INDEX('Glider Types'!$H:$H,MATCH(D13,'Glider Types'!$A:$A,0)),"") -> 185 | M13: =IFERROR(INDEX('Glider Types'!$I:$I,MATCH(D13,'Glider Types'!$A:$A,0)),"") -> 85
A14: SUGAR | B14: Sugarbush Soaring | C14: Schweizer 1-26E | D14: 1-26 | E14: N1107S | F14: 1 | G14: $79/h non-member; $40 member | H14: Yes | I14: Small | J14: =IFERROR(INDEX('Glider Types'!$F:$F,MATCH(D14,'Glider Types'!$A:$A,0)),"") -> 23 | K14: =IFERROR(INDEX('Glider Types'!$G:$G,MATCH(D14,'Glider Types'!$A:$A,0)),"") -> 46 | L14: =IFERROR(INDEX('Glider Types'!$H:$H,MATCH(D14,'Glider Types'!$A:$A,0)),"") -> 161 | M14: =IFERROR(INDEX('Glider Types'!$I:$I,MATCH(D14,'Glider Types'!$A:$A,0)),"") -> 99
A15: MOHAWK | B15: Mohawk Soaring Club | C15: LET L-13 Blanik | D15: L-13 | E15: N336MS | F15: 2 | H15: Members | I15: Roomy | J15: =IFERROR(INDEX('Glider Types'!$F:$F,MATCH(D15,'Glider Types'!$A:$A,0)),"") -> 28 | K15: =IFERROR(INDEX('Glider Types'!$G:$G,MATCH(D15,'Glider Types'!$A:$A,0)),"") -> 46 | L15: =IFERROR(INDEX('Glider Types'!$H:$H,MATCH(D15,'Glider Types'!$A:$A,0)),"") -> 161 | M15: =IFERROR(INDEX('Glider Types'!$I:$I,MATCH(D15,'Glider Types'!$A:$A,0)),"") -> 137
A16: MOHAWK | B16: Mohawk Soaring Club | C16: Schweizer 2-33A | D16: 2-33 | E16: N1186S | F16: 2 | H16: Members | I16: Roomy | J16: =IFERROR(INDEX('Glider Types'!$F:$F,MATCH(D16,'Glider Types'!$A:$A,0)),"") -> 23 | K16: =IFERROR(INDEX('Glider Types'!$G:$G,MATCH(D16,'Glider Types'!$A:$A,0)),"") -> 39 | L16: =IFERROR(INDEX('Glider Types'!$H:$H,MATCH(D16,'Glider Types'!$A:$A,0)),"") -> 185 | M16: =IFERROR(INDEX('Glider Types'!$I:$I,MATCH(D16,'Glider Types'!$A:$A,0)),"") -> 85
A17: MOHAWK | B17: Mohawk Soaring Club | C17: Schweizer 2-33A | D17: 2-33 | E17: N2039T | F17: 2 | H17: Members | I17: Roomy | J17: =IFERROR(INDEX('Glider Types'!$F:$F,MATCH(D17,'Glider Types'!$A:$A,0)),"") -> 23 | K17: =IFERROR(INDEX('Glider Types'!$G:$G,MATCH(D17,'Glider Types'!$A:$A,0)),"") -> 39 | L17: =IFERROR(INDEX('Glider Types'!$H:$H,MATCH(D17,'Glider Types'!$A:$A,0)),"") -> 185 | M17: =IFERROR(INDEX('Glider Types'!$I:$I,MATCH(D17,'Glider Types'!$A:$A,0)),"") -> 85
A18: MOHAWK | B18: Mohawk Soaring Club | C18: Schweizer 2-22E | D18: 2-22 | E18: N2729Z | F18: 2 | H18: Members | I18: Small; may be inactive | J18: =IFERROR(INDEX('Glider Types'!$F:$F,MATCH(D18,'Glider Types'!$A:$A,0)),"") -> 17 | K18: =IFERROR(INDEX('Glider Types'!$G:$G,MATCH(D18,'Glider Types'!$A:$A,0)),"") -> 42 | L18: =IFERROR(INDEX('Glider Types'!$H:$H,MATCH(D18,'Glider Types'!$A:$A,0)),"") -> 197 | M18: =IFERROR(INDEX('Glider Types'!$I:$I,MATCH(D18,'Glider Types'!$A:$A,0)),"") -> 63
A19: MOHAWK | B19: Mohawk Soaring Club | C19: Schweizer 1-26E | D19: 1-26 | E19: N65947 | F19: 1 | H19: Members | I19: Small | J19: =IFERROR(INDEX('Glider Types'!$F:$F,MATCH(D19,'Glider Types'!$A:$A,0)),"") -> 23 | K19: =IFERROR(INDEX('Glider Types'!$G:$G,MATCH(D19,'Glider Types'!$A:$A,0)),"") -> 46 | L19: =IFERROR(INDEX('Glider Types'!$H:$H,MATCH(D19,'Glider Types'!$A:$A,0)),"") -> 161 | M19: =IFERROR(INDEX('Glider Types'!$I:$I,MATCH(D19,'Glider Types'!$A:$A,0)),"") -> 99
A20: MOHAWK | B20: Mohawk Soaring Club | C20: Schweizer 1-23H-15 | D20: 1-23 | E20: N10388 | F20: 1 | H20: Members | I20: Small; may be inactive | J20: =IFERROR(INDEX('Glider Types'!$F:$F,MATCH(D20,'Glider Types'!$A:$A,0)),"") -> 29 | K20: =IFERROR(INDEX('Glider Types'!$G:$G,MATCH(D20,'Glider Types'!$A:$A,0)),"") -> 43 | L20: =IFERROR(INDEX('Glider Types'!$H:$H,MATCH(D20,'Glider Types'!$A:$A,0)),"") -> 138 | M20: =IFERROR(INDEX('Glider Types'!$I:$I,MATCH(D20,'Glider Types'!$A:$A,0)),"") -> 121
A21: POSTMILLS | B21: Post Mills Soaring Club | C21: Schweizer 2-33A | D21: 2-33 | E21: N17967 | F21: 2 | G21: In dues | H21: Members | I21: Roomy | J21: =IFERROR(INDEX('Glider Types'!$F:$F,MATCH(D21,'Glider Types'!$A:$A,0)),"") -> 23 | K21: =IFERROR(INDEX('Glider Types'!$G:$G,MATCH(D21,'Glider Types'!$A:$A,0)),"") -> 39 | L21: =IFERROR(INDEX('Glider Types'!$H:$H,MATCH(D21,'Glider Types'!$A:$A,0)),"") -> 185 | M21: =IFERROR(INDEX('Glider Types'!$I:$I,MATCH(D21,'Glider Types'!$A:$A,0)),"") -> 85
A22: POSTMILLS | B22: Post Mills Soaring Club | C22: LET L-23 Super Blanik | D22: L-23 | E22: N303BA | F22: 2 | G22: In dues | H22: Members | I22: Roomy | J22: =IFERROR(INDEX('Glider Types'!$F:$F,MATCH(D22,'Glider Types'!$A:$A,0)),"") -> 28 | K22: =IFERROR(INDEX('Glider Types'!$G:$G,MATCH(D22,'Glider Types'!$A:$A,0)),"") -> 49 | L22: =IFERROR(INDEX('Glider Types'!$H:$H,MATCH(D22,'Glider Types'!$A:$A,0)),"") -> 148 | M22: =IFERROR(INDEX('Glider Types'!$I:$I,MATCH(D22,'Glider Types'!$A:$A,0)),"") -> 135
A23: POSTMILLS | B23: Post Mills Soaring Club | C23: Schweizer 1-26E | D23: 1-26 | E23: N1115S | F23: 1 | G23: In dues | H23: Members | I23: Small | J23: =IFERROR(INDEX('Glider Types'!$F:$F,MATCH(D23,'Glider Types'!$A:$A,0)),"") -> 23 | K23: =IFERROR(INDEX('Glider Types'!$G:$G,MATCH(D23,'Glider Types'!$A:$A,0)),"") -> 46 | L23: =IFERROR(INDEX('Glider Types'!$H:$H,MATCH(D23,'Glider Types'!$A:$A,0)),"") -> 161 | M23: =IFERROR(INDEX('Glider Types'!$I:$I,MATCH(D23,'Glider Types'!$A:$A,0)),"") -> 99
A24: POSTMILLS | B24: Post Mills Soaring Club | C24: HpH 304C | D24: HPH304 | E24: N304PM | F24: 1 | G24: In dues | H24: Members | I24: Unverified | J24: =IFERROR(INDEX('Glider Types'!$F:$F,MATCH(D24,'Glider Types'!$A:$A,0)),"") -> 43 | K24: =IFERROR(INDEX('Glider Types'!$G:$G,MATCH(D24,'Glider Types'!$A:$A,0)),"") -> 57 | L24: =IFERROR(INDEX('Glider Types'!$H:$H,MATCH(D24,'Glider Types'!$A:$A,0)),"") -> 114 | M24: =IFERROR(INDEX('Glider Types'!$I:$I,MATCH(D24,'Glider Types'!$A:$A,0)),"") -> 146
A25: NESA | B25: New England Soaring Association | C25: Schweizer 2-33 | D25: 2-33 | E25: N2041T | F25: 2 | G25: $10/flight | H25: Members | J25: =IFERROR(INDEX('Glider Types'!$F:$F,MATCH(D25,'Glider Types'!$A:$A,0)),"") -> 23 | K25: =IFERROR(INDEX('Glider Types'!$G:$G,MATCH(D25,'Glider Types'!$A:$A,0)),"") -> 39 | L25: =IFERROR(INDEX('Glider Types'!$H:$H,MATCH(D25,'Glider Types'!$A:$A,0)),"") -> 185 | M25: =IFERROR(INDEX('Glider Types'!$I:$I,MATCH(D25,'Glider Types'!$A:$A,0)),"") -> 85
A26: NESA | B26: New England Soaring Association | C26: Schweizer 2-33A | D26: 2-33 | E26: N1242S | F26: 2 | G26: $10/flight | H26: Members | J26: =IFERROR(INDEX('Glider Types'!$F:$F,MATCH(D26,'Glider Types'!$A:$A,0)),"") -> 23 | K26: =IFERROR(INDEX('Glider Types'!$G:$G,MATCH(D26,'Glider Types'!$A:$A,0)),"") -> 39 | L26: =IFERROR(INDEX('Glider Types'!$H:$H,MATCH(D26,'Glider Types'!$A:$A,0)),"") -> 185 | M26: =IFERROR(INDEX('Glider Types'!$I:$I,MATCH(D26,'Glider Types'!$A:$A,0)),"") -> 85
A27: NESA | B27: New England Soaring Association | C27: Schweizer 1-34 | D27: 1-34 | E27: N7660 | F27: 1 | G27: $10/flight | H27: Members | J27: =IFERROR(INDEX('Glider Types'!$F:$F,MATCH(D27,'Glider Types'!$A:$A,0)),"") -> 34 | K27: =IFERROR(INDEX('Glider Types'!$G:$G,MATCH(D27,'Glider Types'!$A:$A,0)),"") -> 46 | L27: =IFERROR(INDEX('Glider Types'!$H:$H,MATCH(D27,'Glider Types'!$A:$A,0)),"") -> 132 | M27: =IFERROR(INDEX('Glider Types'!$I:$I,MATCH(D27,'Glider Types'!$A:$A,0)),"") -> 114
A28: NESA | B28: New England Soaring Association | C28: Schweizer 1-26E | D28: 1-26 | E28: N65948 | F28: 1 | G28: $10/flight | H28: Members | I28: Small | J28: =IFERROR(INDEX('Glider Types'!$F:$F,MATCH(D28,'Glider Types'!$A:$A,0)),"") -> 23 | K28: =IFERROR(INDEX('Glider Types'!$G:$G,MATCH(D28,'Glider Types'!$A:$A,0)),"") -> 46 | L28: =IFERROR(INDEX('Glider Types'!$H:$H,MATCH(D28,'Glider Types'!$A:$A,0)),"") -> 161 | M28: =IFERROR(INDEX('Glider Types'!$I:$I,MATCH(D28,'Glider Types'!$A:$A,0)),"") -> 99
A29: FRANCONIA | B29: Franconia Soaring Association | C29: Grob G103 Twin Astir | D29: G103 | E29: N103GV | F29: 2 | H29: Members? | I29: Large cockpit; best bet | J29: =IFERROR(INDEX('Glider Types'!$F:$F,MATCH(D29,'Glider Types'!$A:$A,0)),"") -> 36.5 | K29: =IFERROR(INDEX('Glider Types'!$G:$G,MATCH(D29,'Glider Types'!$A:$A,0)),"") -> 57 | L29: =IFERROR(INDEX('Glider Types'!$H:$H,MATCH(D29,'Glider Types'!$A:$A,0)),"") -> 122 | M29: =IFERROR(INDEX('Glider Types'!$I:$I,MATCH(D29,'Glider Types'!$A:$A,0)),"") -> 135
A30: FRANCONIA | B30: Franconia Soaring Association | C30: LET L-23 Super Blanik | D30: L-23 | E30: N118BB | F30: 2 | H30: Members? | I30: Roomy | J30: =IFERROR(INDEX('Glider Types'!$F:$F,MATCH(D30,'Glider Types'!$A:$A,0)),"") -> 28 | K30: =IFERROR(INDEX('Glider Types'!$G:$G,MATCH(D30,'Glider Types'!$A:$A,0)),"") -> 49 | L30: =IFERROR(INDEX('Glider Types'!$H:$H,MATCH(D30,'Glider Types'!$A:$A,0)),"") -> 148 | M30: =IFERROR(INDEX('Glider Types'!$I:$I,MATCH(D30,'Glider Types'!$A:$A,0)),"") -> 135
A31: FRANCONIA | B31: Franconia Soaring Association | C31: Schweizer 2-33A | D31: 2-33 | E31: N33968 | F31: 2 | H31: Members? | I31: Roomy | J31: =IFERROR(INDEX('Glider Types'!$F:$F,MATCH(D31,'Glider Types'!$A:$A,0)),"") -> 23 | K31: =IFERROR(INDEX('Glider Types'!$G:$G,MATCH(D31,'Glider Types'!$A:$A,0)),"") -> 39 | L31: =IFERROR(INDEX('Glider Types'!$H:$H,MATCH(D31,'Glider Types'!$A:$A,0)),"") -> 185 | M31: =IFERROR(INDEX('Glider Types'!$I:$I,MATCH(D31,'Glider Types'!$A:$A,0)),"") -> 85
A32: FRANCONIA | B32: Franconia Soaring Association | C32: Schweizer 2-33A | D32: 2-33 | E32: N7776S | F32: 2 | H32: Members? | I32: Roomy | J32: =IFERROR(INDEX('Glider Types'!$F:$F,MATCH(D32,'Glider Types'!$A:$A,0)),"") -> 23 | K32: =IFERROR(INDEX('Glider Types'!$G:$G,MATCH(D32,'Glider Types'!$A:$A,0)),"") -> 39 | L32: =IFERROR(INDEX('Glider Types'!$H:$H,MATCH(D32,'Glider Types'!$A:$A,0)),"") -> 185 | M32: =IFERROR(INDEX('Glider Types'!$I:$I,MATCH(D32,'Glider Types'!$A:$A,0)),"") -> 85
A33: FRANCONIA | B33: Franconia Soaring Association | C33: Schweizer 1-26 | D33: 1-26 | E33: N2775Z | F33: 1 | H33: Members? | I33: Small | J33: =IFERROR(INDEX('Glider Types'!$F:$F,MATCH(D33,'Glider Types'!$A:$A,0)),"") -> 23 | K33: =IFERROR(INDEX('Glider Types'!$G:$G,MATCH(D33,'Glider Types'!$A:$A,0)),"") -> 46 | L33: =IFERROR(INDEX('Glider Types'!$H:$H,MATCH(D33,'Glider Types'!$A:$A,0)),"") -> 161 | M33: =IFERROR(INDEX('Glider Types'!$I:$I,MATCH(D33,'Glider Types'!$A:$A,0)),"") -> 99
A34: FRANCONIA | B34: Franconia Soaring Association | C34: Schweizer 1-26E | D34: 1-26 | E34: N606GF | F34: 1 | H34: Members? | I34: Small | J34: =IFERROR(INDEX('Glider Types'!$F:$F,MATCH(D34,'Glider Types'!$A:$A,0)),"") -> 23 | K34: =IFERROR(INDEX('Glider Types'!$G:$G,MATCH(D34,'Glider Types'!$A:$A,0)),"") -> 46 | L34: =IFERROR(INDEX('Glider Types'!$H:$H,MATCH(D34,'Glider Types'!$A:$A,0)),"") -> 161 | M34: =IFERROR(INDEX('Glider Types'!$I:$I,MATCH(D34,'Glider Types'!$A:$A,0)),"") -> 99
A35: FRANCONIA | B35: Franconia Soaring Association | C35: Pilatus B4 | D35: B4 | E35: N76PS | F35: 1 | H35: Members? | I35: Smallish | J35: =IFERROR(INDEX('Glider Types'!$F:$F,MATCH(D35,'Glider Types'!$A:$A,0)),"") -> 35 | K35: =IFERROR(INDEX('Glider Types'!$G:$G,MATCH(D35,'Glider Types'!$A:$A,0)),"") -> 46 | L35: =IFERROR(INDEX('Glider Types'!$H:$H,MATCH(D35,'Glider Types'!$A:$A,0)),"") -> 126 | M35: =IFERROR(INDEX('Glider Types'!$I:$I,MATCH(D35,'Glider Types'!$A:$A,0)),"") -> 130
A36: CSA | B36: Connecticut Soaring Association | C36: Schweizer 2-33A | D36: 2-33 | E36: N2930H | F36: 2 | H36: Members | J36: =IFERROR(INDEX('Glider Types'!$F:$F,MATCH(D36,'Glider Types'!$A:$A,0)),"") -> 23 | K36: =IFERROR(INDEX('Glider Types'!$G:$G,MATCH(D36,'Glider Types'!$A:$A,0)),"") -> 39 | L36: =IFERROR(INDEX('Glider Types'!$H:$H,MATCH(D36,'Glider Types'!$A:$A,0)),"") -> 185 | M36: =IFERROR(INDEX('Glider Types'!$I:$I,MATCH(D36,'Glider Types'!$A:$A,0)),"") -> 85
A37: CSA | B37: Connecticut Soaring Association | C37: Schweizer 2-33A | D37: 2-33 | E37: N1228S | F37: 2 | H37: Members | J37: =IFERROR(INDEX('Glider Types'!$F:$F,MATCH(D37,'Glider Types'!$A:$A,0)),"") -> 23 | K37: =IFERROR(INDEX('Glider Types'!$G:$G,MATCH(D37,'Glider Types'!$A:$A,0)),"") -> 39 | L37: =IFERROR(INDEX('Glider Types'!$H:$H,MATCH(D37,'Glider Types'!$A:$A,0)),"") -> 185 | M37: =IFERROR(INDEX('Glider Types'!$I:$I,MATCH(D37,'Glider Types'!$A:$A,0)),"") -> 85
A38: CSA | B38: Connecticut Soaring Association | C38: Schweizer 1-26E | D38: 1-26 | E38: N2517H | F38: 1 | H38: Members | I38: Small | J38: =IFERROR(INDEX('Glider Types'!$F:$F,MATCH(D38,'Glider Types'!$A:$A,0)),"") -> 23 | K38: =IFERROR(INDEX('Glider Types'!$G:$G,MATCH(D38,'Glider Types'!$A:$A,0)),"") -> 46 | L38: =IFERROR(INDEX('Glider Types'!$H:$H,MATCH(D38,'Glider Types'!$A:$A,0)),"") -> 161 | M38: =IFERROR(INDEX('Glider Types'!$I:$I,MATCH(D38,'Glider Types'!$A:$A,0)),"") -> 99
A39: CSA | B39: Connecticut Soaring Association | C39: Schweizer 1-34 | D39: 1-34 | E39: N1164S | F39: 1 | H39: Members | J39: =IFERROR(INDEX('Glider Types'!$F:$F,MATCH(D39,'Glider Types'!$A:$A,0)),"") -> 34 | K39: =IFERROR(INDEX('Glider Types'!$G:$G,MATCH(D39,'Glider Types'!$A:$A,0)),"") -> 46 | L39: =IFERROR(INDEX('Glider Types'!$H:$H,MATCH(D39,'Glider Types'!$A:$A,0)),"") -> 132 | M39: =IFERROR(INDEX('Glider Types'!$I:$I,MATCH(D39,'Glider Types'!$A:$A,0)),"") -> 114
A40: WURTS | B40: Wurtsboro Airport / Wurtsboro Flight Mgmt | C40: Grob G103A Twin II | D40: G103 | E40: not found | F40: 2 | G40: $75/h | H40: Yes | I40: Depends on proportions | J40: =IFERROR(INDEX('Glider Types'!$F:$F,MATCH(D40,'Glider Types'!$A:$A,0)),"") -> 36.5 | K40: =IFERROR(INDEX('Glider Types'!$G:$G,MATCH(D40,'Glider Types'!$A:$A,0)),"") -> 57 | L40: =IFERROR(INDEX('Glider Types'!$H:$H,MATCH(D40,'Glider Types'!$A:$A,0)),"") -> 122 | M40: =IFERROR(INDEX('Glider Types'!$I:$I,MATCH(D40,'Glider Types'!$A:$A,0)),"") -> 135
...

Sheet Travel
A1: Tier | B1: Destination | C1: Carriers (nonstop from BOS) | D1: Friday evening timing | E1: Round-trip fare (KAYAK typical) | F1: Nearest soaring
A2: A | B2: ORD / MDW | C2: AA, UA / WN | D2: ~8-9 pm dep, arr ~10-11 pm CT | E2: $181-308 typ | F2: Sky Soaring ~0:50; Chicago Glider Club ~1:00
A3: A | B3: PHL | C3: AA, DL, B6 | D3: 9:29 pm -> 11:09 pm | E3: $191-347 typ | F3: Van Sant ~1:15; Blairstown ~1:45
A4: A | B4: DCA | C4: AA, DL, B6 | D4: earlier than 10:48 pm | E4: $185-332 typ | F4: Fairfield PA ~1:30; Skyline
A5: A | B5: BWI | C5: WN, DL | D5: 10:20 pm -> ~12:00 am | E5: $213-364; last-minute +103% | F5: Fairfield PA ~1:20
A6: A | B6: ATL | C6: DL, B6, F9 | D6: ~8 pm dep | E6: $196-360 typ | F6: Chilhowee ~2:15; MGSA ~1:00
A7: A | B7: MCO | C7: B6, DL, F9 | D7: 7-8 pm dep | E7: $209-395 typ | F7: Seminole-Lake ~0:45
A8: A | B8: SYR / BUF | C8: AA, B6, DL | D8: ~8:30-9:50 pm | E8: $197-338 typ | F8: Harris Hill 1:45-2:30
A9: A | B9: RDU | C9: DL, B6, F9 | D9: 9:45 pm -> 11:56 pm | E9: $182-346 typ | F9: NCSA ~0:45
A10: B | B10: DEN | C10: UA, WN, B6, DL | D10: 9:06 pm -> 11:48 pm MT | E10: $278-468; avg $365 | F10: Boulder ~0:45
A11: B | B11: CLT | C11: AA, DL | D11: 8:10 pm -> 10:44 pm | E11: $296-429 | F11: Bermuda High ~1:15
A12: B | B12: IAD | C12: UA | D12: 7:41 pm (tight) | E12: $226-377 | F12: Skyline, Eastern Soaring
... A22: C | B22: RNO | C22: none nonstop | D22: n/a | E22: n/a | F22: Minden: not reachable Friday night
A24: Tier A: plausibly under $300 booked 2-3 days out. Tier B: sometimes, watch for sales. Tier C: rarely.
A25: Fares from KAYAK route pages, Sept 2026; booking within 2 weeks runs 10-100% above average. Spirit ceased operations 2 May 2026.
A26: Earliest realistic BOS departure leaving Newton at 5:30 pm Friday: about 7:00-7:15 pm.

Sheet Contact Log
A1: Date | B1: Operator ID | C1: Operator | D1: Person | E1: Method | F1: What I asked | G1: Outcome | H1: Next step | I1: Status
A2: 2026-09-22 (example) | B2: SUGAR | C2: =IFERROR(INDEX(Operators!$B:$B,MATCH(B2,Operators!$A:$A,0)),"") -> Sugarbush Soaring | D2: Front desk | E2: Phone | F2: Rental checkout rules for licensed visitor; which ship fits a tall pilot | G2: (example row) | H2: Book checkout day | I2: Not started
C3: =IFERROR(INDEX(Operators!$B:$B,MATCH(B3,Operators!$A:$A,0)),"")
C4: =IFERROR(INDEX(Operators!$B:$B,MATCH(B4,Operators!$A:$A,0)),"")
C5: =IFERROR(INDEX(Operators!$B:$B,MATCH(B5,Operators!$A:$A,0)),"")
C6: =IFERROR(INDEX(Operators!$B:$B,MATCH(B6,Operators!$A:$A,0)),"")
C7: =IFERROR(INDEX(Operators!$B:$B,MATCH(B7,Operators!$A:$A,0)),"")
C8: =IFERROR(INDEX(Operators!$B:$B,MATCH(B8,Operators!$A:$A,0)),"")
C9: =IFERROR(INDEX(Operators!$B:$B,MATCH(B9,Operators!$A:$A,0)),"")
C10: =IFERROR(INDEX(Operators!$B:$B,MATCH(B10,Operators!$A:$A,0)),"")
C11: =IFERROR(INDEX(Operators!$B:$B,MATCH(B11,Operators!$A:$A,0)),"")
C12: =IFERROR(INDEX(Operators!$B:$B,MATCH(B12,Operators!$A:$A,0)),"")
C13: =IFERROR(INDEX(Operators!$B:$B,MATCH(B13,Operators!$A:$A,0)),"")
C14: =IFERROR(INDEX(Operators!$B:$B,MATCH(B14,Operators!$A:$A,0)),"")
... C59: =IFERROR(INDEX(Operators!$B:$B,MATCH(B59,Operators!$A:$A,0)),"")
